[2024-12-26T13:18:49.676+0000] {taskinstance.py:1165} INFO - Dependencies all met for <TaskInstance: xcom_dag.t2 scheduled__2024-12-25T00:00:00+00:00 [queued]>
[2024-12-26T13:18:49.687+0000] {taskinstance.py:1165} INFO - Dependencies all met for <TaskInstance: xcom_dag.t2 scheduled__2024-12-25T00:00:00+00:00 [queued]>
[2024-12-26T13:18:49.688+0000] {taskinstance.py:1362} INFO - 
--------------------------------------------------------------------------------
[2024-12-26T13:18:49.689+0000] {taskinstance.py:1363} INFO - Starting attempt 1 of 1
[2024-12-26T13:18:49.689+0000] {taskinstance.py:1364} INFO - 
--------------------------------------------------------------------------------
[2024-12-26T13:18:49.708+0000] {taskinstance.py:1383} INFO - Executing <Task(PythonOperator): t2> on 2024-12-25 00:00:00+00:00
[2024-12-26T13:18:49.714+0000] {standard_task_runner.py:55} INFO - Started process 838 to run task
[2024-12-26T13:18:49.717+0000] {standard_task_runner.py:82} INFO - Running: ['***', 'tasks', 'run', 'xcom_dag', 't2', 'scheduled__2024-12-25T00:00:00+00:00', '--job-id', '56', '--raw', '--subdir', 'DAGS_FOLDER/xcom_dag.py', '--cfg-path', '/tmp/tmpsez4oirl']
[2024-12-26T13:18:49.718+0000] {standard_task_runner.py:83} INFO - Job 56: Subtask t2
[2024-12-26T13:18:49.783+0000] {task_command.py:376} INFO - Running <TaskInstance: xcom_dag.t2 scheduled__2024-12-25T00:00:00+00:00 [running]> on host caf53c1f5416
[2024-12-26T13:18:49.860+0000] {taskinstance.py:1592} INFO - Exporting the following env vars:
AIRFLOW_CTX_DAG_OWNER=***
AIRFLOW_CTX_DAG_ID=xcom_dag
AIRFLOW_CTX_TASK_ID=t2
AIRFLOW_CTX_EXECUTION_DATE=2024-12-25T00:00:00+00:00
AIRFLOW_CTX_TRY_NUMBER=1
AIRFLOW_CTX_DAG_RUN_ID=scheduled__2024-12-25T00:00:00+00:00
[2024-12-26T13:18:49.862+0000] {taskinstance.py:1851} ERROR - Task failed with exception
Traceback (most recent call last):
  File "/home/airflow/.local/lib/python3.7/site-packages/airflow/operators/python.py", line 175, in execute
    return_value = self.execute_callable()
  File "/home/airflow/.local/lib/python3.7/site-packages/airflow/operators/python.py", line 193, in execute_callable
    return self.python_callable(*self.op_args, **self.op_kwargs)
  File "/opt/airflow/dags/xcom_dag.py", line 11, in _t2
    ti.xcom_pull(key = 'my_key', task_ids = 't1')
NameError: name 'ti' is not defined
[2024-12-26T13:18:49.878+0000] {taskinstance.py:1406} INFO - Marking task as FAILED. dag_id=xcom_dag, task_id=t2, execution_date=20241225T000000, start_date=20241226T131849, end_date=20241226T131849
[2024-12-26T13:18:49.894+0000] {standard_task_runner.py:105} ERROR - Failed to execute job 56 for task t2 (name 'ti' is not defined; 838)
[2024-12-26T13:18:49.929+0000] {local_task_job.py:164} INFO - Task exited with return code 1
[2024-12-26T13:18:49.963+0000] {local_task_job.py:273} INFO - 0 downstream tasks scheduled from follow-on schedule check
